<?xml version="1.0"?>
<robot name="surveillance_robot" xmlns:xacro="http://www.ros.org/wiki/xacro">

  <link name="base_link">
    <visual><origin xyz="0 0 0" rpy="0 0 0"/>
      <geometry><box size="0.4 0.3 0.1"/></geometry>
      <material name="blue"><color rgba="0.2 0.4 0.8 1"/></material></visual>
    <collision><origin xyz="0 0 0" rpy="0 0 0"/>
      <geometry><box size="0.4 0.3 0.1"/></geometry></collision>
    <inertial><mass value="5.0"/><origin xyz="0 0 0" rpy="0 0 0"/>
      <inertia ixx="0.1" ixy="0" ixz="0" iyy="0.1" iyz="0" izz="0.1"/></inertial>
  </link>

  <joint name="left_wheel_joint" type="continuous">
    <parent link="base_link"/><child link="left_wheel"/>
    <origin xyz="0.0 0.175 -0.05" rpy="-1.5707 0 0"/>
    <axis xyz="0 0 1"/>
  </joint>
  <link name="left_wheel">
    <visual><geometry><cylinder radius="0.08" length="0.04"/></geometry>
      <material name="black"><color rgba="0.1 0.1 0.1 1"/></material></visual>
    <collision><geometry><cylinder radius="0.08" length="0.04"/></geometry></collision>
    <inertial><mass value="0.5"/>
      <inertia ixx="0.001" ixy="0" ixz="0" iyy="0.001" iyz="0" izz="0.001"/></inertial>
  </link>

  <joint name="right_wheel_joint" type="continuous">
    <parent link="base_link"/><child link="right_wheel"/>
    <origin xyz="0.0 -0.175 -0.05" rpy="-1.5707 0 0"/>
    <axis xyz="0 0 1"/>
  </joint>
  <link name="right_wheel">
    <visual><geometry><cylinder radius="0.08" length="0.04"/></geometry>
      <material name="black"><color rgba="0.1 0.1 0.1 1"/></material></visual>
    <collision><geometry><cylinder radius="0.08" length="0.04"/></geometry></collision>
    <inertial><mass value="0.5"/>
      <inertia ixx="0.001" ixy="0" ixz="0" iyy="0.001" iyz="0" izz="0.001"/></inertial>
  </link>

  <joint name="caster_joint" type="fixed">
    <parent link="base_link"/><child link="caster_wheel"/>
    <origin xyz="-0.15 0.0 -0.09" rpy="0 0 0"/>
  </joint>
  <link name="caster_wheel">
    <visual><geometry><sphere radius="0.04"/></geometry>
      <material name="grey"><color rgba="0.6 0.6 0.6 1"/></material></visual>
    <collision><geometry><sphere radius="0.04"/></geometry></collision>
    <inertial><mass value="0.1"/>
      <inertia ixx="0.0001" ixy="0" ixz="0" iyy="0.0001" iyz="0" izz="0.0001"/></inertial>
  </link>

  <joint name="camera_joint" type="fixed">
    <parent link="base_link"/><child link="camera_link"/>
    <origin xyz="0.2 0 0.08" rpy="0 0 0"/>
  </joint>
  <link name="camera_link">
    <visual><geometry><box size="0.05 0.05 0.05"/></geometry>
      <material name="cam_black"><color rgba="0.05 0.05 0.05 1"/></material></visual>
    <collision><geometry><box size="0.05 0.05 0.05"/></geometry></collision>
    <inertial><mass value="0.1"/>
      <inertia ixx="0.0001" ixy="0" ixz="0" iyy="0.0001" iyz="0" izz="0.0001"/></inertial>
  </link>

  <gazebo reference="caster_wheel">
    <mu1>0.0</mu1><mu2>0.0</mu2>
    <kp>1000000.0</kp><kd>100.0</kd>
  </gazebo>
  <gazebo reference="left_wheel">
    <mu1>1.5</mu1><mu2>1.5</mu2>
    <kp>1000000.0</kp><kd>100.0</kd>
  </gazebo>
  <gazebo reference="right_wheel">
    <mu1>1.5</mu1><mu2>1.5</mu2>
    <kp>1000000.0</kp><kd>100.0</kd>
  </gazebo>

  <gazebo reference="camera_link">
    <sensor type="camera" name="surveillance_camera">
      <update_rate>30</update_rate>
      <camera>
        <horizontal_fov>1.3962634</horizontal_fov>
        <image><width>640</width><height>480</height><format>R8G8B8</format></image>
        <clip><near>0.1</near><far>100</far></clip>
      </camera>
      <plugin name="camera_controller" filename="libgazebo_ros_camera.so">
        <ros><remapping>image_raw:=/camera/image_raw</remapping></ros>
        <camera_name>surveillance_camera</camera_name>
        <frame_name>camera_link</frame_name>
      </plugin>
    </sensor>
  </gazebo>

  <gazebo>
    <plugin name="diff_drive" filename="libgazebo_ros_diff_drive.so">
      <ros><remapping>cmd_vel:=/cmd_vel</remapping></ros>
      <left_joint>left_wheel_joint</left_joint>
      <right_joint>right_wheel_joint</right_joint>
      <wheel_separation>0.35</wheel_separation>
      <wheel_diameter>0.16</wheel_diameter>
      <max_wheel_torque>20</max_wheel_torque>
      <publish_odom>true</publish_odom>
      <publish_odom_tf>true</publish_odom_tf>
      <publish_wheel_tf>true</publish_wheel_tf>
      <odometry_frame>odom</odometry_frame>
      <robot_base_frame>base_link</robot_base_frame>
    </plugin>
  </gazebo>

</robot>
